Exception ignored in: <module 'threading' from '/Library/Frameworks/Python.framework/Versions/3.11/lib/python3.11/threading.py'>
Traceback (most recent call last):
  File "/Library/Frameworks/Python.framework/Versions/3.11/lib/python3.11/threading.py", line 1583, in _shutdown
    lock.acquire()
  File "/Library/Frameworks/Python.framework/Versions/3.11/lib/python3.11/site-packages/streamlit/web/bootstrap.py", line 69, in signal_handler
    server.stop()
  File "/Library/Frameworks/Python.framework/Versions/3.11/lib/python3.11/site-packages/streamlit/web/server/server.py", line 397, in stop
    self._runtime.stop()
  File "/Library/Frameworks/Python.framework/Versions/3.11/lib/python3.11/site-packages/streamlit/runtime/runtime.py", line 308, in stop
    async_objs.eventloop.call_soon_threadsafe(stop_on_eventloop)
  File "/Library/Frameworks/Python.framework/Versions/3.11/lib/python3.11/asyncio/base_events.py", line 803, in call_soon_threadsafe
    self._check_closed()
  File "/Library/Frameworks/Python.framework/Versions/3.11/lib/python3.11/asyncio/base_events.py", line 519, in _check_closed
    raise RuntimeError('Event loop is closed')
RuntimeError: Event loop is closed
